2018-11-22 17:14:27,866 ERROR: Exception on / [GET] [in /Users/xuci/Documents/workspace-python/flask-blog/venv/lib/python3.6/site-packages/flask/app.py:1761]
Traceback (most recent call last):
  File "/Users/xuci/Documents/workspace-python/flask-blog/venv/lib/python3.6/site-packages/flask/app.py", line 2292, in wsgi_app
    response = self.full_dispatch_request()
  File "/Users/xuci/Documents/workspace-python/flask-blog/venv/lib/python3.6/site-packages/flask/app.py", line 1815, in full_dispatch_request
    rv = self.handle_user_exception(e)
  File "/Users/xuci/Documents/workspace-python/flask-blog/venv/lib/python3.6/site-packages/flask/app.py", line 1718, in handle_user_exception
    reraise(exc_type, exc_value, tb)
  File "/Users/xuci/Documents/workspace-python/flask-blog/venv/lib/python3.6/site-packages/flask/_compat.py", line 35, in reraise
    raise value
  File "/Users/xuci/Documents/workspace-python/flask-blog/venv/lib/python3.6/site-packages/flask/app.py", line 1813, in full_dispatch_request
    rv = self.dispatch_request()
  File "/Users/xuci/Documents/workspace-python/flask-blog/venv/lib/python3.6/site-packages/flask/app.py", line 1799, in dispatch_request
    return self.view_functions[rule.endpoint](**req.view_args)
  File "/Users/xuci/Documents/workspace-python/flask-blog/venv/lib/python3.6/site-packages/flask_login/utils.py", line 261, in decorated_view
    return func(*args, **kwargs)
  File "/Users/xuci/Documents/workspace-python/flask-blog/app/main/routes.py", line 43, in index
    return render_template('index.html', title='Home Page', form=form, posts=posts.items, next_url=next_url, prev_url=prev_url)
  File "/Users/xuci/Documents/workspace-python/flask-blog/venv/lib/python3.6/site-packages/flask/templating.py", line 135, in render_template
    context, ctx.app)
  File "/Users/xuci/Documents/workspace-python/flask-blog/venv/lib/python3.6/site-packages/flask/templating.py", line 117, in _render
    rv = template.render(context)
  File "/Users/xuci/Documents/workspace-python/flask-blog/venv/lib/python3.6/site-packages/jinja2/asyncsupport.py", line 76, in render
    return original_render(self, *args, **kwargs)
  File "/Users/xuci/Documents/workspace-python/flask-blog/venv/lib/python3.6/site-packages/jinja2/environment.py", line 1008, in render
    return self.environment.handle_exception(exc_info, True)
  File "/Users/xuci/Documents/workspace-python/flask-blog/venv/lib/python3.6/site-packages/jinja2/environment.py", line 780, in handle_exception
    reraise(exc_type, exc_value, tb)
  File "/Users/xuci/Documents/workspace-python/flask-blog/venv/lib/python3.6/site-packages/jinja2/_compat.py", line 37, in reraise
    raise value.with_traceback(tb)
  File "/Users/xuci/Documents/workspace-python/flask-blog/app/templates/index.html", line 2, in top-level template code
    {% import 'bootstrap/wtf.html' as wtf %}
  File "/Users/xuci/Documents/workspace-python/flask-blog/app/templates/base/base.html", line 1, in top-level template code
    {% extends 'bootstrap/base.html' %}
  File "/Users/xuci/Documents/workspace-python/flask-blog/venv/lib/python3.6/site-packages/flask_bootstrap/templates/bootstrap/base.html", line 1, in top-level template code
    {% block doc -%}
  File "/Users/xuci/Documents/workspace-python/flask-blog/venv/lib/python3.6/site-packages/flask_bootstrap/templates/bootstrap/base.html", line 4, in block "doc"
    {%- block html %}
  File "/Users/xuci/Documents/workspace-python/flask-blog/venv/lib/python3.6/site-packages/flask_bootstrap/templates/bootstrap/base.html", line 20, in block "html"
    {% block body -%}
  File "/Users/xuci/Documents/workspace-python/flask-blog/venv/lib/python3.6/site-packages/flask_bootstrap/templates/bootstrap/base.html", line 23, in block "body"
    {% block content -%}
  File "/Users/xuci/Documents/workspace-python/flask-blog/app/templates/base/base.html", line 49, in block "content"
    {% block app_content %}
  File "/Users/xuci/Documents/workspace-python/flask-blog/app/templates/index.html", line 11, in block "app_content"
    {% include 'base/_post.html' %}
  File "/Users/xuci/Documents/workspace-python/flask-blog/app/templates/base/_post.html", line 9, in top-level template code
    <a href="{{ url_for('mian.userprofile', username=post.author.username) }}">
  File "/Users/xuci/Documents/workspace-python/flask-blog/venv/lib/python3.6/site-packages/flask/helpers.py", line 356, in url_for
    return appctx.app.handle_url_build_error(error, endpoint, values)
  File "/Users/xuci/Documents/workspace-python/flask-blog/venv/lib/python3.6/site-packages/flask/app.py", line 2061, in handle_url_build_error
    reraise(exc_type, exc_value, tb)
  File "/Users/xuci/Documents/workspace-python/flask-blog/venv/lib/python3.6/site-packages/flask/_compat.py", line 35, in reraise
    raise value
  File "/Users/xuci/Documents/workspace-python/flask-blog/venv/lib/python3.6/site-packages/flask/helpers.py", line 345, in url_for
    force_external=external)
  File "/Users/xuci/Documents/workspace-python/flask-blog/venv/lib/python3.6/site-packages/werkzeug/routing.py", line 1776, in build
    raise BuildError(endpoint, values, method, self)
werkzeug.routing.BuildError: Could not build url for endpoint 'mian.userprofile' with values ['username']. Did you mean 'main.userprofile' instead?
