2018-09-07 17:05:38,840 INFO: Blog startup [in /Users/xuci/Documents/workspace-python/flask-blog/blog.py:28]
2018-09-07 17:06:04,504 ERROR: Exception on /edit_profile [POST] [in /Users/xuci/Documents/workspace-python/flask-blog/venv/lib/python3.6/site-packages/flask/app.py:1761]
Traceback (most recent call last):
  File "/Users/xuci/Documents/workspace-python/flask-blog/venv/lib/python3.6/site-packages/sqlalchemy/engine/base.py", line 1193, in _execute_context
    context)
  File "/Users/xuci/Documents/workspace-python/flask-blog/venv/lib/python3.6/site-packages/sqlalchemy/engine/default.py", line 509, in do_execute
    cursor.execute(statement, parameters)
sqlite3.IntegrityError: UNIQUE constraint failed: user.username

The above exception was the direct cause of the following exception:

Traceback (most recent call last):
  File "/Users/xuci/Documents/workspace-python/flask-blog/venv/lib/python3.6/site-packages/flask/app.py", line 2292, in wsgi_app
    response = self.full_dispatch_request()
  File "/Users/xuci/Documents/workspace-python/flask-blog/venv/lib/python3.6/site-packages/flask/app.py", line 1815, in full_dispatch_request
    rv = self.handle_user_exception(e)
  File "/Users/xuci/Documents/workspace-python/flask-blog/venv/lib/python3.6/site-packages/flask/app.py", line 1718, in handle_user_exception
    reraise(exc_type, exc_value, tb)
  File "/Users/xuci/Documents/workspace-python/flask-blog/venv/lib/python3.6/site-packages/flask/_compat.py", line 35, in reraise
    raise value
  File "/Users/xuci/Documents/workspace-python/flask-blog/venv/lib/python3.6/site-packages/flask/app.py", line 1813, in full_dispatch_request
    rv = self.dispatch_request()
  File "/Users/xuci/Documents/workspace-python/flask-blog/venv/lib/python3.6/site-packages/flask/app.py", line 1799, in dispatch_request
    return self.view_functions[rule.endpoint](**req.view_args)
  File "/Users/xuci/Documents/workspace-python/flask-blog/venv/lib/python3.6/site-packages/flask_login/utils.py", line 261, in decorated_view
    return func(*args, **kwargs)
  File "/Users/xuci/Documents/workspace-python/flask-blog/app/routes.py", line 96, in edit_profile
    db.session.commit()
  File "/Users/xuci/Documents/workspace-python/flask-blog/venv/lib/python3.6/site-packages/sqlalchemy/orm/scoping.py", line 153, in do
    return getattr(self.registry(), name)(*args, **kwargs)
  File "/Users/xuci/Documents/workspace-python/flask-blog/venv/lib/python3.6/site-packages/sqlalchemy/orm/session.py", line 943, in commit
    self.transaction.commit()
  File "/Users/xuci/Documents/workspace-python/flask-blog/venv/lib/python3.6/site-packages/sqlalchemy/orm/session.py", line 467, in commit
    self._prepare_impl()
  File "/Users/xuci/Documents/workspace-python/flask-blog/venv/lib/python3.6/site-packages/sqlalchemy/orm/session.py", line 447, in _prepare_impl
    self.session.flush()
  File "/Users/xuci/Documents/workspace-python/flask-blog/venv/lib/python3.6/site-packages/sqlalchemy/orm/session.py", line 2254, in flush
    self._flush(objects)
  File "/Users/xuci/Documents/workspace-python/flask-blog/venv/lib/python3.6/site-packages/sqlalchemy/orm/session.py", line 2380, in _flush
    transaction.rollback(_capture_exception=True)
  File "/Users/xuci/Documents/workspace-python/flask-blog/venv/lib/python3.6/site-packages/sqlalchemy/util/langhelpers.py", line 66, in __exit__
    compat.reraise(exc_type, exc_value, exc_tb)
  File "/Users/xuci/Documents/workspace-python/flask-blog/venv/lib/python3.6/site-packages/sqlalchemy/util/compat.py", line 249, in reraise
    raise value
  File "/Users/xuci/Documents/workspace-python/flask-blog/venv/lib/python3.6/site-packages/sqlalchemy/orm/session.py", line 2344, in _flush
    flush_context.execute()
  File "/Users/xuci/Documents/workspace-python/flask-blog/venv/lib/python3.6/site-packages/sqlalchemy/orm/unitofwork.py", line 391, in execute
    rec.execute(self)
  File "/Users/xuci/Documents/workspace-python/flask-blog/venv/lib/python3.6/site-packages/sqlalchemy/orm/unitofwork.py", line 556, in execute
    uow
  File "/Users/xuci/Documents/workspace-python/flask-blog/venv/lib/python3.6/site-packages/sqlalchemy/orm/persistence.py", line 177, in save_obj
    mapper, table, update)
  File "/Users/xuci/Documents/workspace-python/flask-blog/venv/lib/python3.6/site-packages/sqlalchemy/orm/persistence.py", line 768, in _emit_update_statements
    execute(statement, multiparams)
  File "/Users/xuci/Documents/workspace-python/flask-blog/venv/lib/python3.6/site-packages/sqlalchemy/engine/base.py", line 948, in execute
    return meth(self, multiparams, params)
  File "/Users/xuci/Documents/workspace-python/flask-blog/venv/lib/python3.6/site-packages/sqlalchemy/sql/elements.py", line 269, in _execute_on_connection
    return connection._execute_clauseelement(self, multiparams, params)
  File "/Users/xuci/Documents/workspace-python/flask-blog/venv/lib/python3.6/site-packages/sqlalchemy/engine/base.py", line 1060, in _execute_clauseelement
    compiled_sql, distilled_params
  File "/Users/xuci/Documents/workspace-python/flask-blog/venv/lib/python3.6/site-packages/sqlalchemy/engine/base.py", line 1200, in _execute_context
    context)
  File "/Users/xuci/Documents/workspace-python/flask-blog/venv/lib/python3.6/site-packages/sqlalchemy/engine/base.py", line 1413, in _handle_dbapi_exception
    exc_info
  File "/Users/xuci/Documents/workspace-python/flask-blog/venv/lib/python3.6/site-packages/sqlalchemy/util/compat.py", line 265, in raise_from_cause
    reraise(type(exception), exception, tb=exc_tb, cause=cause)
  File "/Users/xuci/Documents/workspace-python/flask-blog/venv/lib/python3.6/site-packages/sqlalchemy/util/compat.py", line 248, in reraise
    raise value.with_traceback(tb)
  File "/Users/xuci/Documents/workspace-python/flask-blog/venv/lib/python3.6/site-packages/sqlalchemy/engine/base.py", line 1193, in _execute_context
    context)
  File "/Users/xuci/Documents/workspace-python/flask-blog/venv/lib/python3.6/site-packages/sqlalchemy/engine/default.py", line 509, in do_execute
    cursor.execute(statement, parameters)
sqlalchemy.exc.IntegrityError: (sqlite3.IntegrityError) UNIQUE constraint failed: user.username [SQL: 'UPDATE user SET username=?, about_me=? WHERE user.id = ?'] [parameters: ('susan', '', 2)] (Background on this error at: http://sqlalche.me/e/gkpj)
2018-09-07 18:09:13,358 INFO: Blog startup [in /Users/xuci/Documents/workspace-python/flask-blog/blog.py:28]
2018-09-07 18:09:17,408 ERROR: Exception on /edit_profile [POST] [in /Users/xuci/Documents/workspace-python/flask-blog/venv/lib/python3.6/site-packages/flask/app.py:1761]
Traceback (most recent call last):
  File "/Users/xuci/Documents/workspace-python/flask-blog/venv/lib/python3.6/site-packages/flask/app.py", line 2292, in wsgi_app
    response = self.full_dispatch_request()
  File "/Users/xuci/Documents/workspace-python/flask-blog/venv/lib/python3.6/site-packages/flask/app.py", line 1815, in full_dispatch_request
    rv = self.handle_user_exception(e)
  File "/Users/xuci/Documents/workspace-python/flask-blog/venv/lib/python3.6/site-packages/flask/app.py", line 1718, in handle_user_exception
    reraise(exc_type, exc_value, tb)
  File "/Users/xuci/Documents/workspace-python/flask-blog/venv/lib/python3.6/site-packages/flask/_compat.py", line 35, in reraise
    raise value
  File "/Users/xuci/Documents/workspace-python/flask-blog/venv/lib/python3.6/site-packages/flask/app.py", line 1813, in full_dispatch_request
    rv = self.dispatch_request()
  File "/Users/xuci/Documents/workspace-python/flask-blog/venv/lib/python3.6/site-packages/flask/app.py", line 1799, in dispatch_request
    return self.view_functions[rule.endpoint](**req.view_args)
  File "/Users/xuci/Documents/workspace-python/flask-blog/venv/lib/python3.6/site-packages/flask_login/utils.py", line 261, in decorated_view
    return func(*args, **kwargs)
  File "/Users/xuci/Documents/workspace-python/flask-blog/app/routes.py", line 92, in edit_profile
    form = EditProfileForm(original_username=current_user.username)
  File "/Users/xuci/Documents/workspace-python/flask-blog/venv/lib/python3.6/site-packages/wtforms/form.py", line 212, in __call__
    return type.__call__(cls, *args, **kwargs)
  File "/Users/xuci/Documents/workspace-python/flask-blog/app/forms.py", line 38, in __init__
    super(EditProfileForm, self.__init__(*args, **kwargs))
TypeError: __init__() missing 1 required positional argument: 'original_username'
